Workbook

Sheet Financial Status
A1: Chun Wo Construction & Engineering Company Limited
Q2: Print Date: 2026-01-13
A3: Project Code: | B3: 968
A4: Project Name: | B4: Contract No. DC/2018/09 Rehabilitation of Trunk Sewers in Tuen Mun
A5: Report Date: | B5: 2025-12-31
A6: Start Date: | B6: 2018-12-28 | G6: Monthly Financial Report
A7: Complete Date: | B7: 2023-03-31 Time Consumed (%): | C7: =IFERROR((B5-B6)/(LEFT(B7, FIND(REPT(" ", 32), B7))-B6), "") | P7: Confidential
A8: Target Complete Date: | B8: 2023-12-01 Target Completed (%): | C8: =IFERROR((B5-B6)/(LEFT(B8, FIND(REPT(" ", 32), B8))-B6), "")
A11: (HK$'000) | G11: Financial Status
A12: Item | B12: Trade | C12: Budget | G12: Business Plan | H12: Audit Report (WIP) | I12: Adjustment Cost / Variation | J12: Projection | K12: Committed Value / Cost | N12: Accrual (Before Retention) | O12: Cash Flow
C13: Tender | D13: 1st Working Budget | E13: Adjustment Cost/ variation | F13: Revision as at | O13: Actual received & paid | Q13: Balance to
J14: as at | K14: as at | L14: % of time elapse | M14: Balance | N14: as at | O14: as at | P14: % of time elapse
C15: A | D15: B | E15: C | F15: D=B+C | H15: J | I15: k=I-J | J15: I | K15: E | L15: E1=E/D | M15: F=D-E | O15: G | P15: G1=G/E | Q15: H=E-G
A16: 1 | B16: Income | I16: =IF(H16="", "", J16-H16) | J16: =IF(ISBLANK(Projection!P13), "", Projection!P13) | K16: =IF(ISBLANK('Committed Cost'!P13), "", 'Committed Cost'!P13) | L16: =IFERROR(IF(ISBLANK(F16), "", K16/F16), 0) | M16: =IF(F16="", "", F16-K16) | N16: =IF(ISBLANK(Accrual!P13), "", Accrual!P13) | O16: =IF(ISBLANK('Cash Flow'!P13), "",'Cash Flow'!P13) | P16: =IFERROR(IF(O16="", "", O16/K16), 0) | Q16: =IF(K16="", "", K16-O16)
A17: 1.1 | B17: Original Contract Works | C17: 205000 | D17: 205000 | E17: 0 | F17: =D17+E17 -> 205000 | G17: 205000 | H17: 205000 | I17: =IF(H17="", "", J17-H17) -> 0 | J17: =IF(ISBLANK(Projection!P14), "", Projection!P14) -> 205000 | K17: =IF(ISBLANK('Committed Cost'!P14), "", 'Committed Cost'!P14) -> 205000 | L17: =IFERROR(IF(ISBLANK(F17), "", K17/F17), 0) -> 1 | M17: =IF(F17="", "", F17-K17) -> 0 | N17: =IF(ISBLANK(Accrual!P14), "", Accrual!P14) -> 428279.83 | O17: =IF(ISBLANK('Cash Flow'!P14), "",'Cash Flow'!P14) -> 428280.16 | P17: =IFERROR(IF(O17="", "", O17/K17), 0) -> 2.0891715 | Q17: =IF(K17="", "", K17-O17) -> -223280.16
A18: 1.2 | B18: V.O. / Compensation Events | I18: =IF(H18="", "", J18-H18) | J18: =IF(ISBLANK(Projection!P15), "", Projection!P15) | K18: =IF(ISBLANK('Committed Cost'!P15), "", 'Committed Cost'!P15) | L18: =IFERROR(IF(ISBLANK(F18), "", K18/F18), 0) | M18: =IF(F18="", "", F18-K18) | N18: =IF(ISBLANK(Accrual!P15), "", Accrual!P15) | O18: =IF(ISBLANK('Cash Flow'!P15), "",'Cash Flow'!P15) | P18: =IFERROR(IF(O18="", "", O18/K18), 0) | Q18: =IF(K18="", "", K18-O18)
A19: 1.2.1 | B19: -V.O. / C.E. | C19: 5476.51 | D19: 25383.56 | E19: 0 | F19: =D19+E19 -> 25383.56 | G19: 126723.4 | H19: 126723.4 | I19: =IF(H19="", "", J19-H19) -> 0 | J19: =IF(ISBLANK(Projection!P16), "", Projection!P16) -> 126723.4 | K19: =IF(ISBLANK('Committed Cost'!P16), "", 'Committed Cost'!P16) -> 71713.6 | L19: =IFERROR(IF(ISBLANK(F19), "", K19/F19), 0) -> 2.8251987 | M19: =IF(F19="", "", F19-K19) -> -46330.04 | N19: =IF(ISBLANK(Accrual!P16), "", Accrual!P16) -> 0 | O19: =IF(ISBLANK('Cash Flow'!P16), "",'Cash Flow'!P16) -> 0 | P19: =IFERROR(IF(O19="", "", O19/K19), 0) -> 0 | Q19: =IF(K19="", "", K19-O19) -> 71713.6
A20: 1.2.2 | B20: -Fee of C.E. | C20: 0 | D20: 0 | E20: 0 | F20: =D20+E20 -> 0 | G20: 25480.08 | H20: 25480.08 | I20: =IF(H20="", "", J20-H20) -> 0 | J20: =IF(ISBLANK(Projection!P17), "", Projection!P17) -> 25480.08 | K20: =IF(ISBLANK('Committed Cost'!P17), "", 'Committed Cost'!P17) -> 14311.16 | L20: =IFERROR(IF(ISBLANK(F20), "", K20/F20), 0) -> 0 | M20: =IF(F20="", "", F20-K20) -> -14311.16 | N20: =IF(ISBLANK(Accrual!P17), "", Accrual!P17) -> 0 | O20: =IF(ISBLANK('Cash Flow'!P17), "",'Cash Flow'!P17) -> 0 | P20: =IFERROR(IF(O20="", "", O20/K20), 0) -> 0 | Q20: =IF(K20="", "", K20-O20) -> 14311.16
A21: 1.3 | B21: Provisional Sum | C21: 0 | D21: 0 | E21: 0 | F21: =D21+E21 -> 0 | G21: 0 | H21: 0 | I21: =IF(H21="", "", J21-H21) -> 0 | J21: =IF(ISBLANK(Projection!P18), "", Projection!P18) -> 0 | K21: =IF(ISBLANK('Committed Cost'!P18), "", 'Committed Cost'!P18) -> 0 | L21: =IFERROR(IF(ISBLANK(F21), "", K21/F21), 0) -> 0 | M21: =IF(F21="", "", F21-K21) -> 0 | N21: =IF(ISBLANK(Accrual!P18), "", Accrual!P18) -> 0 | O21: =IF(ISBLANK('Cash Flow'!P18), "",'Cash Flow'!P18) -> 0 | P21: =IFERROR(IF(O21="", "", O21/K21), 0) -> 0 | Q21: =IF(K21="", "", K21-O21) -> 0
A22: 1.4 | B22: Adjustment for Provisional Quantities (remeasurement) and PC Rates | C22: 0 | D22: 0 | E22: 0 | F22: =D22+E22 -> 0 | G22: 0 | H22: 0 | I22: =IF(H22="", "", J22-H22) -> 0 | J22: =IF(ISBLANK(Projection!P19), "", Projection!P19) -> 0 | K22: =IF(ISBLANK('Committed Cost'!P19), "", 'Committed Cost'!P19) -> 0 | L22: =IFERROR(IF(ISBLANK(F22), "", K22/F22), 0) -> 0 | M22: =IF(F22="", "", F22-K22) -> 0 | N22: =IF(ISBLANK(Accrual!P19), "", Accrual!P19) -> 0 | O22: =IF(ISBLANK('Cash Flow'!P19), "",'Cash Flow'!P19) -> 0 | P22: =IFERROR(IF(O22="", "", O22/K22), 0) -> 0 | Q22: =IF(K22="", "", K22-O22) -> 0
A23: 1.5 | B23: NSC | C23: 0 | D23: 0 | E23: 0 | F23: =D23+E23 -> 0 | G23: 0 | H23: 0 | I23: =IF(H23="", "", J23-H23) -> 0 | J23: =IF(ISBLANK(Projection!P20), "", Projection!P20) -> 0 | K23: =IF(ISBLANK('Committed Cost'!P20), "", 'Committed Cost'!P20) -> 0 | L23: =IFERROR(IF(ISBLANK(F23), "", K23/F23), 0) -> 0 | M23: =IF(F23="", "", F23-K23) -> 0 | N23: =IF(ISBLANK(Accrual!P20), "", Accrual!P20) -> 0 | O23: =IF(ISBLANK('Cash Flow'!P20), "",'Cash Flow'!P20) -> 0 | P23: =IFERROR(IF(O23="", "", O23/K23), 0) -> 0 | Q23: =IF(K23="", "", K23-O23) -> 0
A24: 1.6 | B24: Profit & Attendance | C24: 0 | D24: 0 | E24: 0 | F24: =D24+E24 -> 0 | G24: 0 | H24: 0 | I24: =IF(H24="", "", J24-H24) -> 0 | J24: =IF(ISBLANK(Projection!P21), "", Projection!P21) -> 0 | K24: =IF(ISBLANK('Committed Cost'!P21), "", 'Committed Cost'!P21) -> 0 | L24: =IFERROR(IF(ISBLANK(F24), "", K24/F24), 0) -> 0 | M24: =IF(F24="", "", F24-K24) -> 0 | N24: =IF(ISBLANK(Accrual!P21), "", Accrual!P21) -> 0 | O24: =IF(ISBLANK('Cash Flow'!P21), "",'Cash Flow'!P21) -> 0 | P24: =IFERROR(IF(O24="", "", O24/K24), 0) -> 0 | Q24: =IF(K24="", "", K24-O24) -> 0
A25: 1.7 | B25: Claims | C25: 0 | D25: 0 | E25: 0 | F25: =D25+E25 -> 0 | G25: 0 | H25: 0 | I25: =IF(H25="", "", J25-H25) -> 0 | J25: =IF(ISBLANK(Projection!P22), "", Projection!P22) -> 0 | K25: =IF(ISBLANK('Committed Cost'!P22), "", 'Committed Cost'!P22) -> 0 | L25: =IFERROR(IF(ISBLANK(F25), "", K25/F25), 0) -> 0 | M25: =IF(F25="", "", F25-K25) -> 0 | N25: =IF(ISBLANK(Accrual!P22), "", Accrual!P22) -> 0 | O25: =IF(ISBLANK('Cash Flow'!P22), "",'Cash Flow'!P22) -> 0 | P25: =IFERROR(IF(O25="", "", O25/K25), 0) -> 0 | Q25: =IF(K25="", "", K25-O25) -> 0
A26: 1.8 | B26: Price Fluctuation / CPF | C26: 6124.68 | D26: 13371.87 | E26: 0 | F26: =D26+E26 -> 13371.87 | G26: 52516.54 | H26: 52516.54 | I26: =IF(H26="", "", J26-H26) -> 0 | J26: =IF(ISBLANK(Projection!P23), "", Projection!P23) -> 52516.54 | K26: =IF(ISBLANK('Committed Cost'!P23), "", 'Committed Cost'!P23) -> 52429.896 | L26: =IFERROR(IF(ISBLANK(F26), "", K26/F26), 0) -> 3.9209098 | M26: =IF(F26="", "", F26-K26) -> -39058.026 | N26: =IF(ISBLANK(Accrual!P23), "", Accrual!P23) -> 0 | O26: =IF(ISBLANK('Cash Flow'!P23), "",'Cash Flow'!P23) -> 0 | P26: =IFERROR(IF(O26="", "", O26/K26), 0) -> 0 | Q26: =IF(K26="", "", K26-O26) -> 52429.896
A27: 1.9 | B27: MPF Reimbursement | C27: 0 | D27: 0 | E27: 0 | F27: =D27+E27 -> 0 | G27: 0 | H27: 0 | I27: =IF(H27="", "", J27-H27) -> 0 | J27: =IF(ISBLANK(Projection!P24), "", Projection!P24) -> 0 | K27: =IF(ISBLANK('Committed Cost'!P24), "", 'Committed Cost'!P24) -> 0 | L27: =IFERROR(IF(ISBLANK(F27), "", K27/F27), 0) -> 0 | M27: =IF(F27="", "", F27-K27) -> 0 | N27: =IF(ISBLANK(Accrual!P24), "", Accrual!P24) -> 0 | O27: =IF(ISBLANK('Cash Flow'!P24), "",'Cash Flow'!P24) -> 0 | P27: =IFERROR(IF(O27="", "", O27/K27), 0) -> 0 | Q27: =IF(K27="", "", K27-O27) -> 0
A28: 1.10 | B28: SA | C28: 0 | D28: 0 | E28: 0 | F28: =D28+E28 -> 0 | G28: 0 | H28: 0 | I28: =IF(H28="", "", J28-H28) -> 0 | J28: =IF(ISBLANK(Projection!P25), "", Projection!P25) -> 0 | K28: =IF(ISBLANK('Committed Cost'!P25), "", 'Committed Cost'!P25) -> 0 | L28: =IFERROR(IF(ISBLANK(F28), "", K28/F28), 0) -> 0 | M28: =IF(F28="", "", F28-K28) -> 0 | N28: =IF(ISBLANK(Accrual!P25), "", Accrual!P25) -> 0 | O28: =IF(ISBLANK('Cash Flow'!P25), "",'Cash Flow'!P25) -> 0.008 | P28: =IFERROR(IF(O28="", "", O28/K28), 0) -> 0 | Q28: =IF(K28="", "", K28-O28) -> -0.008
A29: 1.11 | B29: CSD | C29: 0 | D29: 0 | E29: 0 | F29: =D29+E29 -> 0 | G29: 0 | H29: 0 | I29: =IF(H29="", "", J29-H29) -> 0 | J29: =IF(ISBLANK(Projection!P26), "", Projection!P26) -> 0 | K29: =IF(ISBLANK('Committed Cost'!P26), "", 'Committed Cost'!P26) -> 0 | L29: =IFERROR(IF(ISBLANK(F29), "", K29/F29), 0) -> 0 | M29: =IF(F29="", "", F29-K29) -> 0 | N29: =IF(ISBLANK(Accrual!P26), "", Accrual!P26) -> 0 | O29: =IF(ISBLANK('Cash Flow'!P26), "",'Cash Flow'!P26) -> 0 | P29: =IFERROR(IF(O29="", "", O29/K29), 0) -> 0 | Q29: =IF(K29="", "", K29-O29) -> 0
A30: 1.12 | B30: Other Revenue / Pain Gain Sharing | I30: =IF(H30="", "", J30-H30) | J30: =IF(ISBLANK(Projection!P27), "", Projection!P27) | K30: =IF(ISBLANK('Committed Cost'!P27), "", 'Committed Cost'!P27) | L30: =IFERROR(IF(ISBLANK(F30), "", K30/F30), 0) | M30: =IF(F30="", "", F30-K30) | N30: =IF(ISBLANK(Accrual!P27), "", Accrual!P27) | O30: =IF(ISBLANK('Cash Flow'!P27), "",'Cash Flow'!P27) | P30: =IFERROR(IF(O30="", "", O30/K30), 0) | Q30: =IF(K30="", "", K30-O30)
A31: 1.12.1 | B31: -Other Revenue | C31: 12333 | D31: 12089.6 | E31: 0 | F31: =D31+E31 -> 12089.6 | G31: 3067.819 | H31: 3067.819 | I31: =IF(H31="", "", J31-H31) -> 0 | J31: =IF(ISBLANK(Projection!P28), "", Projection!P28) -> 3067.819 | K31: =IF(ISBLANK('Committed Cost'!P28), "", 'Committed Cost'!P28) -> 2966.76 | L31: =IFERROR(IF(ISBLANK(F31), "", K31/F31), 0) -> 0.2453977 | M31: =IF(F31="", "", F31-K31) -> 9122.84 | N31: =IF(ISBLANK(Accrual!P28), "", Accrual!P28) -> -0.14 | O31: =IF(ISBLANK('Cash Flow'!P28), "",'Cash Flow'!P28) -> -0.038 | P31: =IFERROR(IF(O31="", "", O31/K31), 0) -> -1.2808586e-05 | Q31: =IF(K31="", "", K31-O31) -> 2966.798
A32: 1.12.2 | B32: -Pain Gain Sharing | C32: 0 | D32: 0 | E32: 0 | F32: =D32+E32 -> 0 | G32: 15492.6 | H32: 15492.6 | I32: =IF(H32="", "", J32-H32) -> 0 | J32: =IF(ISBLANK(Projection!P29), "", Projection!P29) -> 15492.6 | K32: =IF(ISBLANK('Committed Cost'!P29), "", 'Committed Cost'!P29) -> -48534.786 | L32: =IFERROR(IF(ISBLANK(F32), "", K32/F32), 0) -> 0 | M32: =IF(F32="", "", F32-K32) -> 48534.786 | N32: =IF(ISBLANK(Accrual!P29), "", Accrual!P29) -> 0.19949 | O32: =IF(ISBLANK('Cash Flow'!P29), "",'Cash Flow'!P29) -> -0.20051 | P32: =IFERROR(IF(O32="", "", O32/K32), 0) -> 4.1312637e-06 | Q32: =IF(K32="", "", K32-O32) -> -48534.585
A33: 1.12.3 | B33: -Stretch Target Income | C33: 0 | D33: 0 | E33: 0 | F33: =D33+E33 -> 0 | G33: 0 | H33: 0 | I33: =IF(H33="", "", J33-H33) -> 0 | J33: =IF(ISBLANK(Projection!P30), "", Projection!P30) -> 0 | K33: =IF(ISBLANK('Committed Cost'!P30), "", 'Committed Cost'!P30) -> 0 | L33: =IFERROR(IF(ISBLANK(F33), "", K33/F33), 0) -> 0 | M33: =IF(F33="", "", F33-K33) -> 0 | N33: =IF(ISBLANK(Accrual!P30), "", Accrual!P30) -> 0 | O33: =IF(ISBLANK('Cash Flow'!P30), "",'Cash Flow'!P30) -> 0 | P33: =IFERROR(IF(O33="", "", O33/K33), 0) -> 0 | Q33: =IF(K33="", "", K33-O33) -> 0
A34: 1.13 | B34: Less :LD | C34: 0 | D34: 0 | E34: 0 | F34: =D34+E34 -> 0 | G34: 0 | H34: 0 | I34: =IF(H34="", "", J34-H34) -> 0 | J34: =IF(ISBLANK(Projection!P31), "", Projection!P31) -> 0 | K34: =IF(ISBLANK('Committed Cost'!P31), "", 'Committed Cost'!P31) -> 0 | L34: =IFERROR(IF(ISBLANK(F34), "", K34/F34), 0) -> 0 | M34: =IF(F34="", "", F34-K34) -> 0 | N34: =IF(ISBLANK(Accrual!P31), "", Accrual!P31) -> 0 | O34: =IF(ISBLANK('Cash Flow'!P31), "",'Cash Flow'!P31) -> 0 | P34: =IFERROR(IF(O34="", "", O34/K34), 0) -> 0 | Q34: =IF(K34="", "", K34-O34) -> 0
A35: 1.14 | B35: Less :Retention Money | C35: 0 | D35: 0 | E35: 0 | F35: =D35+E35 -> 0 | G35: 0 | H35: 0 | I35: =IF(H35="", "", J35-H35) -> 0 | J35: =IF(ISBLANK(Projection!P32), "", Projection!P32) -> 0 | K35: =IF(ISBLANK('Committed Cost'!P32), "", 'Committed Cost'!P32) -> 0 | L35: =IFERROR(IF(ISBLANK(F35), "", K35/F35), 0) -> 0 | M35: =IF(F35="", "", F35-K35) -> 0 | N35: =IF(ISBLANK(Accrual!P32), "", Accrual!P32) -> 0 | O35: =IF(ISBLANK('Cash Flow'!P32), "",'Cash Flow'!P32) -> -0.24791 | P35: =IFERROR(IF(O35="", "", O35/K35), 0) -> 0 | Q35: =IF(K35="", "", K35-O35) -> 0.24791
A36: 1.15 | B36: Less :Retention Money (NSC) | C36: 0 | D36: 0 | E36: 0 | F36: =D36+E36 -> 0 | G36: 0 | H36: 0 | I36: =IF(H36="", "", J36-H36) -> 0 | J36: =IF(ISBLANK(Projection!P33), "", Projection!P33) -> 0 | K36: =IF(ISBLANK('Committed Cost'!P33), "", 'Committed Cost'!P33) -> 0 | L36: =IFERROR(IF(ISBLANK(F36), "", K36/F36), 0) -> 0 | M36: =IF(F36="", "", F36-K36) -> 0 | N36: =IF(ISBLANK(Accrual!P33), "", Accrual!P33) -> 0 | O36: =IF(ISBLANK('Cash Flow'!P33), "",'Cash Flow'!P33) -> 0 | P36: =IFERROR(IF(O36="", "", O36/K36), 0) -> 0 | Q36: =IF(K36="", "", K36-O36) -> 0
A37: 1.16 | B37: Partialing Income Total | C37: 0 | D37: 0 | E37: 0 | F37: =D37+E37 -> 0 | G37: 0 | H37: 0 | I37: =IF(H37="", "", J37-H37) -> 0 | J37: =IF(ISBLANK(Projection!P34), "", Projection!P34) -> 0 | K37: =IF(ISBLANK('Committed Cost'!P34), "", 'Committed Cost'!P34) -> 0 | L37: =IFERROR(IF(ISBLANK(F37), "", K37/F37), 0) -> 0 | M37: =IF(F37="", "", F37-K37) -> 0 | N37: =IF(ISBLANK(Accrual!P34), "", Accrual!P34) -> 0 | O37: =IF(ISBLANK('Cash Flow'!P34), "",'Cash Flow'!P34) -> 0 | P37: =IFERROR(IF(O37="", "", O37/K37), 0) -> 0 | Q37: =IF(K37="", "", K37-O37) -> 0
A38: 1.17 | B38: Advance Payment | C38: 0 | D38: 0 | E38: 0 | F38: 0 | G38: 0 | H38: 0 | I38: =IF(H38="", "", J38-H38) -> 0 | J38: =IF(ISBLANK(Projection!P35), "", Projection!P35) -> 0 | K38: =IF(ISBLANK('Committed Cost'!P35), "", 'Committed Cost'!P35) -> 0 | L38: =IFERROR(IF(ISBLANK(F38), "", K38/F38), 0) -> 0 | M38: =IF(F38="", "", F38-K38) -> 0 | N38: =IF(ISBLANK(Accrual!P35), "", Accrual!P35) -> 0 | O38: =IF(ISBLANK('Cash Flow'!P35), "",'Cash Flow'!P35) -> 0 | P38: =IFERROR(IF(O38="", "", O38/K38), 0) -> 0 | Q38: =IF(K38="", "", K38-O38) -> 0
B39: Total Income | C39: =SUM(C15:C38) -> 228934.19 | D39: =SUM(D15:D38) -> 255845.03 | E39: =SUM(E15:E38) -> 0 | F39: =SUM(F15:F38) -> 255845.03 | G39: =SUM(G15:G38) -> 428280.44 | H39: =SUM(H15:H38) -> 428280.44 | I39: =IF(H39="", "", J39-H39) -> 0 | J39: =IF(ISBLANK(Projection!P36), "", Projection!P36) -> 428280.44 | K39: =IF(ISBLANK('Committed Cost'!P36), "", 'Committed Cost'!P36) -> 297886.63 | L39: =IFERROR(IF(ISBLANK(F39), "", K39/F39), 0) -> 1.1643245 | M39: =IF(F39="", "", F39-K39) -> -42041.6 | N39: =IF(ISBLANK(Accrual!P36), "", Accrual!P36) -> 428279.89 | O39: =IF(ISBLANK('Cash Flow'!P36), "",'Cash Flow'!P36) -> 428279.69 | P39: =IFERROR(IF(O39="", "", O39/K39), 0) -> 1.4377271 | Q39: =IF(K39="", "", K39-O39) -> -130393.06
I40: =IF(H40="", "", J40-H40) | J40: =IF(ISBLANK(Projection!P37), "", Projection!P37) | K40: =IF(ISBLANK('Committed Cost'!P37), "", 'Committed Cost'!P37) | L40: =IFERROR(IF(ISBLANK(F40), "", K40/F40), 0) | M40: =IF(F40="", "", F40-K40) | N40: =IF(ISBLANK(Accrual!P37), "", Accrual!P37) | O40: =IF(ISBLANK('Cash Flow'!P37), "",'Cash Flow'!P37) | P40: =IFERROR(IF(O40="", "", O40/K40), 0) | Q40: =IF(K40="", "", K40-O40)
A41: 2 | B41: Less : Cost | I41: =IF(H41="", "", J41-H41) | J41: =IF(ISBLANK(Projection!P38), "", Projection!P38) | K41: =IF(ISBLANK('Committed Cost'!P38), "", 'Committed Cost'!P38) | L41: =IFERROR(IF(ISBLANK(F41), "", K41/F41), 0) | M41: =IF(F41="", "", F41-K41) | N41: =IF(ISBLANK(Accrual!P38), "", Accrual!P38) | O41: =IF(ISBLANK('Cash Flow'!P38), "",'Cash Flow'!P38) | P41: =IFERROR(IF(O41="", "", O41/K41), 0) | Q41: =IF(K41="", "", K41-O41)
A42: 2.1 | B42: Preliminaries | I42: =IF(H42="", "", J42-H42) | J42: =IF(ISBLANK(Projection!P39), "", Projection!P39) | K42: =IF(ISBLANK('Committed Cost'!P39), "", 'Committed Cost'!P39) | L42: =IFERROR(IF(ISBLANK(F42), "", K42/F42), 0) | M42: =IF(F42="", "", F42-K42) | N42: =IF(ISBLANK(Accrual!P39), "", Accrual!P39) | O42: =IF(ISBLANK('Cash Flow'!P39), "",'Cash Flow'!P39) | P42: =IFERROR(IF(O42="", "", O42/K42), 0) | Q42: =IF(K42="", "", K42-O42)
...

Sheet Projection
A1: Chun Wo Construction & Engineering Company Limited
P2: Print Date: 2026-01-13
A3: Project Code: | B3: 968
A4: Project Name: | B4: Contract No. DC/2018/09 Rehabilitation of Trunk Sewers in Tuen Mun
A5: Report Date: | B5: 2025-12-31
A6: Start Date: | B6: 2018-12-28 | G6: Monthly Financial Report
A7: Complete Date: | B7: 2023-03-31 Time Consumed (%): | C7: =IFERROR((B5-B6)/(LEFT(B7, FIND(REPT(" ", 32), B7))-B6), "") | O7: Confidential
A8: Target Complete Date: | B8: 2023-12-01 Target Completed (%): | C8: =IFERROR((B5-B6)/(LEFT(B8, FIND(REPT(" ", 32), B8))-B6), "")
A11: (HK$'000) | G11: Projection
A12: Item | B12: Trade | C12: Bal B/F | D12: Apr | E12: May | F12: Jun | G12: Jul | H12: Aug | I12: Sep | J12: Oct | K12: Nov | L12: Dec | M12: Jan | N12: Feb | O12: Mar | P12: Total
A13: 1 | B13: Income
A14: 1.1 | B14: Original Contract Works | C14: 205000 | D14: 0 | E14: 0 | F14: 0 | G14: 0 | H14: 0 | I14: 0 | J14: 0 | K14: 0 | L14: 0 | P14: =SUM(C14:O14) -> 205000
A15: 1.2 | B15: V.O. / Compensation Events
A16: 1.2.1 | B16: -V.O. / C.E. | C16: 126723.4 | D16: 0 | E16: 0 | F16: 0 | G16: 0 | H16: 0 | I16: 0 | J16: 0 | K16: 0 | L16: 0 | P16: =SUM(C16:O16) -> 126723.4
A17: 1.2.2 | B17: -Fee of C.E. | C17: 25480.08 | D17: 0 | E17: 0 | F17: 0 | G17: 0 | H17: 0 | I17: 0 | J17: 0 | K17: 0 | L17: 0 | P17: =SUM(C17:O17) -> 25480.08
A18: 1.3 | B18: Provisional Sum | C18: 0 | D18: 0 | E18: 0 | F18: 0 | G18: 0 | H18: 0 | I18: 0 | J18: 0 | K18: 0 | L18: 0 | P18: =SUM(C18:O18) -> 0
A19: 1.4 | B19: Adjustment for Provisional Quantities (remeasurement) and PC Rates | C19: 0 | D19: 0 | E19: 0 | F19: 0 | G19: 0 | H19: 0 | I19: 0 | J19: 0 | K19: 0 | L19: 0 | P19: =SUM(C19:O19) -> 0
A20: 1.5 | B20: NSC | C20: 0 | D20: 0 | E20: 0 | F20: 0 | G20: 0 | H20: 0 | I20: 0 | J20: 0 | K20: 0 | L20: 0 | P20: =SUM(C20:O20) -> 0
A21: 1.6 | B21: Profit & Attendance | C21: 0 | D21: 0 | E21: 0 | F21: 0 | G21: 0 | H21: 0 | I21: 0 | J21: 0 | K21: 0 | L21: 0 | P21: =SUM(C21:O21) -> 0
A22: 1.7 | B22: Claims | C22: 0 | D22: 0 | E22: 0 | F22: 0 | G22: 0 | H22: 0 | I22: 0 | J22: 0 | K22: 0 | L22: 0 | P22: =SUM(C22:O22) -> 0
A23: 1.8 | B23: Price Fluctuation / CPF | C23: 52516.54 | D23: 0 | E23: 0 | F23: 0 | G23: 0 | H23: 0 | I23: 0 | J23: 0 | K23: 0 | L23: 0 | P23: =SUM(C23:O23) -> 52516.54
A24: 1.9 | B24: MPF Reimbursement | C24: 0 | D24: 0 | E24: 0 | F24: 0 | G24: 0 | H24: 0 | I24: 0 | J24: 0 | K24: 0 | L24: 0 | P24: =SUM(C24:O24) -> 0
A25: 1.10 | B25: SA | C25: 0 | D25: 0 | E25: 0 | F25: 0 | G25: 0 | H25: 0 | I25: 0 | J25: 0 | K25: 0 | L25: 0 | P25: =SUM(C25:O25) -> 0
A26: 1.11 | B26: CSD | C26: 0 | D26: 0 | E26: 0 | F26: 0 | G26: 0 | H26: 0 | I26: 0 | J26: 0 | K26: 0 | L26: 0 | P26: =SUM(C26:O26) -> 0
A27: 1.12 | B27: Other Revenue / Pain Gain Sharing
A28: 1.12.1 | B28: -Other Revenue | C28: 3067.819 | D28: 0 | E28: 0 | F28: 0 | G28: 0 | H28: 0 | I28: 0 | J28: 0 | K28: 0 | L28: 0 | P28: =SUM(C28:O28) -> 3067.819
A29: 1.12.2 | B29: -Pain Gain Sharing | C29: 15492.6 | D29: 0 | E29: 0 | F29: 0 | G29: 0 | H29: 0 | I29: 0 | J29: 0 | K29: 0 | L29: 0 | P29: =SUM(C29:O29) -> 15492.6
A30: 1.12.3 | B30: -Stretch Target Income | C30: 0 | D30: 0 | E30: 0 | F30: 0 | G30: 0 | H30: 0 | I30: 0 | J30: 0 | K30: 0 | L30: 0 | P30: =SUM(C30:O30) -> 0
A31: 1.13 | B31: Less :LD | C31: 0 | D31: 0 | E31: 0 | F31: 0 | G31: 0 | H31: 0 | I31: 0 | J31: 0 | K31: 0 | L31: 0 | P31: =SUM(C31:O31) -> 0
A32: 1.14 | B32: Less :Retention Money | C32: 0 | D32: 0 | E32: 0 | F32: 0 | G32: 0 | H32: 0 | I32: 0 | J32: 0 | K32: 0 | L32: 0 | P32: =SUM(C32:O32) -> 0
A33: 1.15 | B33: Less :Retention Money (NSC) | C33: 0 | D33: 0 | E33: 0 | F33: 0 | G33: 0 | H33: 0 | I33: 0 | J33: 0 | K33: 0 | L33: 0 | P33: =SUM(C33:O33) -> 0
A34: 1.16 | B34: Partialing Income Total | C34: 0 | D34: 0 | E34: 0 | F34: 0 | G34: 0 | H34: 0 | I34: 0 | J34: 0 | K34: 0 | L34: 0 | P34: =SUM(C34:O34) -> 0
A35: 1.17 | B35: Advance Payment | C35: 0 | D35: 0 | E35: 0 | F35: 0 | G35: 0 | H35: 0 | I35: 0 | J35: 0 | K35: 0 | L35: 0 | P35: =SUM(C35:O35) -> 0
B36: Total Income | C36: =SUM(C13:C35) -> 428280.44 | D36: =SUM(D13:D35) -> 0 | E36: =SUM(E13:E35) -> 0 | F36: =SUM(F13:F35) -> 0 | G36: =SUM(G13:G35) -> 0 | H36: =SUM(H13:H35) -> 0 | I36: =SUM(I13:I35) -> 0 | J36: =SUM(J13:J35) -> 0 | ... P36: =SUM(P13:P35) -> 428280.44
A38: 2 | B38: Less : Cost
A39: 2.1 | B39: Preliminaries
A40: 2.1.1 | B40: -Manpower (Mgt. & Supervision) | C40: 80028.454 | D40: 0 | E40: 0 | F40: 0 | G40: 0 | H40: 0 | I40: 0 | J40: 0 | K40: 0 | L40: 0 | P40: =SUM(C40:O40) -> 80028.454
A41: 2.1.13 | B41: -Manpower (HO-Consultant) | C41: 25 | D41: 0 | E41: 0 | F41: 0 | G41: 20 | H41: 30 | I41: 30 | J41: 0 | K41: 0 | L41: 90 | P41: =SUM(C41:O41) -> 195
A42: 2.1.2 | B42: -Manpower (RE) | C42: 250 | D42: 0 | E42: 0 | F42: 0 | G42: 0 | H42: 0 | I42: 0 | J42: 0 | K42: 0 | L42: 0 | P42: =SUM(C42:O42) -> 250
A43: 2.1.3 | B43: -Manpower (Labour) | C43: 15643 | D43: 0 | E43: 0 | F43: 0 | G43: 0 | H43: 0 | I43: 0 | J43: 0 | K43: 0 | L43: 0 | P43: =SUM(C43:O43) -> 15643
...

Sheet Committed Cost
A1: Chun Wo Construction & Engineering Company Limited
P2: Print Date: 2026-01-13
A3: Project Code: | B3: 968
A4: Project Name: | B4: Contract No. DC/2018/09 Rehabilitation of Trunk Sewers in Tuen Mun
A5: Report Date: | B5: 2025-12-31
A6: Start Date: | B6: 2018-12-28 | G6: Monthly Financial Report
A7: Complete Date: | B7: 2023-03-31 Time Consumed (%): | C7: =IFERROR((B5-B6)/(LEFT(B7, FIND(REPT(" ", 32), B7))-B6), "") | O7: Confidential
A8: Target Complete Date: | B8: 2023-12-01 Target Completed (%): | C8: =IFERROR((B5-B6)/(LEFT(B8, FIND(REPT(" ", 32), B8))-B6), "")
A11: (HK$'000) | G11: Committed Cost
A12: Item | B12: Trade | C12: Bal B/F | D12: Apr | E12: May | F12: Jun | G12: Jul | H12: Aug | I12: Sep | J12: Oct | K12: Nov | L12: Dec | M12: Jan | N12: Feb | O12: Mar | P12: Total
A13: 1 | B13: Income
A14: 1.1 | B14: Original Contract Works | C14: 205000 | D14: 0 | E14: 0 | F14: 0 | G14: 0 | H14: 0 | I14: 0 | J14: 0 | K14: 0 | L14: 0 | P14: =SUM(C14:O14) -> 205000
A15: 1.2 | B15: V.O. / Compensation Events
A16: 1.2.1 | B16: -V.O. / C.E. | C16: 71713.6 | D16: 0 | E16: 0 | F16: 0 | G16: 0 | H16: 0 | I16: 0 | J16: 0 | K16: 0 | L16: 0 | P16: =SUM(C16:O16) -> 71713.6
A17: 1.2.2 | B17: -Fee of C.E. | C17: 14311.16 | D17: 0 | E17: 0 | F17: 0 | G17: 0 | H17: 0 | I17: 0 | J17: 0 | K17: 0 | L17: 0 | P17: =SUM(C17:O17) -> 14311.16
A18: 1.3 | B18: Provisional Sum | C18: 0 | D18: 0 | E18: 0 | F18: 0 | G18: 0 | H18: 0 | I18: 0 | J18: 0 | K18: 0 | L18: 0 | P18: =SUM(C18:O18) -> 0
A19: 1.4 | B19: Adjustment for Provisional Quantities (remeasurement) and PC Rates | C19: 0 | D19: 0 | E19: 0 | F19: 0 | G19: 0 | H19: 0 | I19: 0 | J19: 0 | K19: 0 | L19: 0 | P19: =SUM(C19:O19) -> 0
A20: 1.5 | B20: NSC | C20: 0 | D20: 0 | E20: 0 | F20: 0 | G20: 0 | H20: 0 | I20: 0 | J20: 0 | K20: 0 | L20: 0 | P20: =SUM(C20:O20) -> 0
A21: 1.6 | B21: Profit & Attendance | C21: 0 | D21: 0 | E21: 0 | F21: 0 | G21: 0 | H21: 0 | I21: 0 | J21: 0 | K21: 0 | L21: 0 | P21: =SUM(C21:O21) -> 0
A22: 1.7 | B22: Claims | C22: 0 | D22: 0 | E22: 0 | F22: 0 | G22: 0 | H22: 0 | I22: 0 | J22: 0 | K22: 0 | L22: 0 | P22: =SUM(C22:O22) -> 0
A23: 1.8 | B23: Price Fluctuation / CPF | C23: 52429.896 | D23: 0 | E23: 0 | F23: 0 | G23: 0 | H23: 0 | I23: 0 | J23: 0 | K23: 0 | L23: 0 | P23: =SUM(C23:O23) -> 52429.896
A24: 1.9 | B24: MPF Reimbursement | C24: 0 | D24: 0 | E24: 0 | F24: 0 | G24: 0 | H24: 0 | I24: 0 | J24: 0 | K24: 0 | L24: 0 | P24: =SUM(C24:O24) -> 0
A25: 1.10 | B25: SA | C25: 0 | D25: 0 | E25: 0 | F25: 0 | G25: 0 | H25: 0 | I25: 0 | J25: 0 | K25: 0 | L25: 0 | P25: =SUM(C25:O25) -> 0
A26: 1.11 | B26: CSD | C26: 0 | D26: 0 | E26: 0 | F26: 0 | G26: 0 | H26: 0 | I26: 0 | J26: 0 | K26: 0 | L26: 0 | P26: =SUM(C26:O26) -> 0
A27: 1.12 | B27: Other Revenue / Pain Gain Sharing
A28: 1.12.1 | B28: -Other Revenue | C28: 2966.76 | D28: 0 | E28: 0 | F28: 0 | G28: 0 | H28: 0 | I28: 0 | J28: 0 | K28: 0 | L28: 0 | P28: =SUM(C28:O28) -> 2966.76
A29: 1.12.2 | B29: -Pain Gain Sharing | C29: -48534.786 | D29: 0 | E29: 0 | F29: 0 | G29: 0 | H29: 0 | I29: 0 | J29: 0 | K29: 0 | L29: 0 | P29: =SUM(C29:O29) -> -48534.786
A30: 1.12.3 | B30: -Stretch Target Income | C30: 0 | D30: 0 | E30: 0 | F30: 0 | G30: 0 | H30: 0 | I30: 0 | J30: 0 | K30: 0 | L30: 0 | P30: =SUM(C30:O30) -> 0
A31: 1.13 | B31: Less :LD | C31: 0 | D31: 0 | E31: 0 | F31: 0 | G31: 0 | H31: 0 | I31: 0 | J31: 0 | K31: 0 | L31: 0 | P31: =SUM(C31:O31) -> 0
A32: 1.14 | B32: Less :Retention Money | C32: 0 | D32: 0 | E32: 0 | F32: 0 | G32: 0 | H32: 0 | I32: 0 | J32: 0 | K32: 0 | L32: 0 | P32: =SUM(C32:O32) -> 0
A33: 1.15 | B33: Less :Retention Money (NSC) | C33: 0 | D33: 0 | E33: 0 | F33: 0 | G33: 0 | H33: 0 | I33: 0 | J33: 0 | K33: 0 | L33: 0 | P33: =SUM(C33:O33) -> 0
A34: 1.16 | B34: Partialing Income Total | C34: 0 | D34: 0 | E34: 0 | F34: 0 | G34: 0 | H34: 0 | I34: 0 | J34: 0 | K34: 0 | L34: 0 | P34: =SUM(C34:O34) -> 0
A35: 1.17 | B35: Advance Payment | C35: 0 | D35: 0 | E35: 0 | F35: 0 | G35: 0 | H35: 0 | I35: 0 | J35: 0 | K35: 0 | L35: 0 | P35: =SUM(C35:O35) -> 0
B36: Total Income | C36: =SUM(C13:C35) -> 297886.63 | D36: =SUM(D13:D35) -> 0 | E36: =SUM(E13:E35) -> 0 | F36: =SUM(F13:F35) -> 0 | G36: =SUM(G13:G35) -> 0 | H36: =SUM(H13:H35) -> 0 | I36: =SUM(I13:I35) -> 0 | J36: =SUM(J13:J35) -> 0 | ... P36: =SUM(P13:P35) -> 297886.63
A38: 2 | B38: Less : Cost
A39: 2.1 | B39: Preliminaries
A40: 2.1.1 | B40: -Manpower (Mgt. & Supervision) | C40: 79994.223 | D40: 0 | E40: 0 | F40: 0 | G40: 0 | H40: 0 | I40: 0 | J40: 0 | K40: 0 | L40: 0 | P40: =SUM(C40:O40) -> 79994.223
A41: 2.1.13 | B41: -Manpower (HO-Consultant) | C41: 22.112 | D41: -3 | E41: 3.94 | F41: 0 | G41: 12.69 | H41: 37.34763 | I41: 29.81 | J41: -3.27 | K41: 3.94 | L41: 88.07 | P41: =SUM(C41:O41) -> 191.63963
A42: 2.1.2 | B42: -Manpower (RE) | C42: 122.51203 | D42: 0 | E42: 0 | F42: 0 | G42: 0 | H42: 0 | I42: 0 | J42: 0 | K42: 0 | L42: 0 | P42: =SUM(C42:O42) -> 122.51203
A43: 2.1.3 | B43: -Manpower (Labour) | C43: 15420.888 | D43: 0 | E43: 0 | F43: 0 | G43: 0 | H43: 0 | I43: 0 | J43: 0 | K43: 0 | L43: 0 | P43: =SUM(C43:O43) -> 15420.888
...

Sheet Accrual
A1: Chun Wo Construction & Engineering Company Limited
P2: Print Date: 2026-01-13
A3: Project Code: | B3: 968
A4: Project Name: | B4: Contract No. DC/2018/09 Rehabilitation of Trunk Sewers in Tuen Mun
A5: Report Date: | B5: 2025-12-31
A6: Start Date: | B6: 2018-12-28 | G6: Monthly Financial Report
A7: Complete Date: | B7: 2023-03-31 Time Consumed (%): | C7: =IFERROR((B5-B6)/(LEFT(B7, FIND(REPT(" ", 32), B7))-B6), "") | O7: Confidential
A8: Target Complete Date: | B8: 2023-12-01 Target Completed (%): | C8: =IFERROR((B5-B6)/(LEFT(B8, FIND(REPT(" ", 32), B8))-B6), "")
A11: (HK$'000) | G11: Accrual
A12: Item | B12: Trade | C12: Bal B/F | D12: Apr | E12: May | F12: Jun | G12: Jul | H12: Aug | I12: Sep | J12: Oct | K12: Nov | L12: Dec | M12: Jan | N12: Feb | O12: Mar | P12: Total
A13: 1 | B13: Income
A14: 1.1 | B14: Original Contract Works | C14: 425890.83 | D14: 0 | E14: 0 | F14: 0 | G14: 0 | H14: 0 | I14: 0 | J14: 0 | K14: 0 | L14: 2389 | P14: =SUM(C14:O14) -> 428279.83
A15: 1.2 | B15: V.O. / Compensation Events
A16: 1.2.1 | B16: -V.O. / C.E. | C16: 0 | D16: 0 | E16: 0 | F16: 0 | G16: 0 | H16: 0 | I16: 0 | J16: 0 | K16: 0 | L16: 0 | P16: =SUM(C16:O16) -> 0
A17: 1.2.2 | B17: -Fee of C.E. | C17: 0 | D17: 0 | E17: 0 | F17: 0 | G17: 0 | H17: 0 | I17: 0 | J17: 0 | K17: 0 | L17: 0 | P17: =SUM(C17:O17) -> 0
A18: 1.3 | B18: Provisional Sum | C18: 0 | D18: 0 | E18: 0 | F18: 0 | G18: 0 | H18: 0 | I18: 0 | J18: 0 | K18: 0 | L18: 0 | P18: =SUM(C18:O18) -> 0
A19: 1.4 | B19: Adjustment for Provisional Quantities (remeasurement) and PC Rates | C19: 0 | D19: 0 | E19: 0 | F19: 0 | G19: 0 | H19: 0 | I19: 0 | J19: 0 | K19: 0 | L19: 0 | P19: =SUM(C19:O19) -> 0
A20: 1.5 | B20: NSC | C20: 0 | D20: 0 | E20: 0 | F20: 0 | G20: 0 | H20: 0 | I20: 0 | J20: 0 | K20: 0 | L20: 0 | P20: =SUM(C20:O20) -> 0
A21: 1.6 | B21: Profit & Attendance | C21: 0 | D21: 0 | E21: 0 | F21: 0 | G21: 0 | H21: 0 | I21: 0 | J21: 0 | K21: 0 | L21: 0 | P21: =SUM(C21:O21) -> 0
A22: 1.7 | B22: Claims | C22: 0 | D22: 0 | E22: 0 | F22: 0 | G22: 0 | H22: 0 | I22: 0 | J22: 0 | K22: 0 | L22: 0 | P22: =SUM(C22:O22) -> 0
A23: 1.8 | B23: Price Fluctuation / CPF | C23: 0 | D23: 0 | E23: 0 | F23: 0 | G23: 0 | H23: 0 | I23: 0 | J23: 0 | K23: 0 | L23: 0 | P23: =SUM(C23:O23) -> 0
A24: 1.9 | B24: MPF Reimbursement | C24: 0 | D24: 0 | E24: 0 | F24: 0 | G24: 0 | H24: 0 | I24: 0 | J24: 0 | K24: 0 | L24: 0 | P24: =SUM(C24:O24) -> 0
A25: 1.10 | B25: SA | C25: 0 | D25: 0 | E25: 0 | F25: 0 | G25: 0 | H25: 0 | I25: 0 | J25: 0 | K25: 0 | L25: 0 | P25: =SUM(C25:O25) -> 0
A26: 1.11 | B26: CSD | C26: 0 | D26: 0 | E26: 0 | F26: 0 | G26: 0 | H26: 0 | I26: 0 | J26: 0 | K26: 0 | L26: 0 | P26: =SUM(C26:O26) -> 0
A27: 1.12 | B27: Other Revenue / Pain Gain Sharing
A28: 1.12.1 | B28: -Other Revenue | C28: -0.14 | D28: 0 | E28: 0 | F28: 0 | G28: 0 | H28: 0 | I28: 0 | J28: 0 | K28: 0 | L28: 0 | P28: =SUM(C28:O28) -> -0.14
A29: 1.12.2 | B29: -Pain Gain Sharing | C29: 0.19949 | D29: 0 | E29: 0 | F29: 0 | G29: 0 | H29: 0 | I29: 0 | J29: 0 | K29: 0 | L29: 0 | P29: =SUM(C29:O29) -> 0.19949
A30: 1.12.3 | B30: -Stretch Target Income | C30: 0 | D30: 0 | E30: 0 | F30: 0 | G30: 0 | H30: 0 | I30: 0 | J30: 0 | K30: 0 | L30: 0 | P30: =SUM(C30:O30) -> 0
A31: 1.13 | B31: Less :LD | C31: 0 | D31: 0 | E31: 0 | F31: 0 | G31: 0 | H31: 0 | I31: 0 | J31: 0 | K31: 0 | L31: 0 | P31: =SUM(C31:O31) -> 0
A32: 1.14 | B32: Less :Retention Money | C32: 0 | D32: 0 | E32: 0 | F32: 0 | G32: 0 | H32: 0 | I32: 0 | J32: 0 | K32: 0 | L32: 0 | P32: =SUM(C32:O32) -> 0
A33: 1.15 | B33: Less :Retention Money (NSC) | C33: 0 | D33: 0 | E33: 0 | F33: 0 | G33: 0 | H33: 0 | I33: 0 | J33: 0 | K33: 0 | L33: 0 | P33: =SUM(C33:O33) -> 0
A34: 1.16 | B34: Partialing Income Total | C34: 0 | D34: 0 | E34: 0 | F34: 0 | G34: 0 | H34: 0 | I34: 0 | J34: 0 | K34: 0 | L34: 0 | P34: =SUM(C34:O34) -> 0
A35: 1.17 | B35: Advance Payment | C35: 0 | D35: 0 | E35: 0 | F35: 0 | G35: 0 | H35: 0 | I35: 0 | J35: 0 | K35: 0 | L35: 0 | P35: =SUM(C35:O35) -> 0
B36: Total Income | C36: =SUM(C13:C35) -> 425890.89 | D36: =SUM(D13:D35) -> 0 | E36: =SUM(E13:E35) -> 0 | F36: =SUM(F13:F35) -> 0 | G36: =SUM(G13:G35) -> 0 | H36: =SUM(H13:H35) -> 0 | I36: =SUM(I13:I35) -> 0 | J36: =SUM(J13:J35) -> 0 | ... P36: =SUM(P13:P35) -> 428279.89
A38: 2 | B38: Less : Cost
A39: 2.1 | B39: Preliminaries
A40: 2.1.1 | B40: -Manpower (Mgt. & Supervision) | C40: 79994.034 | D40: 0 | E40: 0 | F40: 0 | G40: 0 | H40: 0 | I40: 0 | J40: 0 | K40: 0 | L40: 0 | P40: =SUM(C40:O40) -> 79994.034
A41: 2.1.13 | B41: -Manpower (HO-Consultant) | C41: 22.112 | D41: -3 | E41: 3.94 | F41: 0 | G41: 12.69 | H41: 37.34763 | I41: 29.81 | J41: -3.27 | K41: 3.94 | L41: 88.07 | P41: =SUM(C41:O41) -> 191.63963
A42: 2.1.2 | B42: -Manpower (RE) | C42: 122.51203 | D42: 0 | E42: 0 | F42: 0 | G42: 0 | H42: 0 | I42: 0 | J42: 0 | K42: 0 | L42: 0 | P42: =SUM(C42:O42) -> 122.51203
A43: 2.1.3 | B43: -Manpower (Labour) | C43: 15420.883 | D43: 0 | E43: 0 | F43: 0 | G43: 0 | H43: 0 | I43: 0 | J43: 0 | K43: 0 | L43: 0 | P43: =SUM(C43:O43) -> 15420.883
...

Sheet Cash Flow
A1: Chun Wo Construction & Engineering Company Limited
P2: Print Date: 2026-01-13
A3: Project Code: | B3: 968
A4: Project Name: | B4: Contract No. DC/2018/09 Rehabilitation of Trunk Sewers in Tuen Mun
A5: Report Date: | B5: 2025-12-31
A6: Start Date: | B6: 2018-12-28 | G6: Monthly Financial Report
A7: Complete Date: | B7: 2023-03-31 Time Consumed (%): | C7: =IFERROR((B5-B6)/(LEFT(B7, FIND(REPT(" ", 32), B7))-B6), "") | O7: Confidential
A8: Target Complete Date: | B8: 2023-12-01 Target Completed (%): | C8: =IFERROR((B5-B6)/(LEFT(B8, FIND(REPT(" ", 32), B8))-B6), "")
A11: (HK$'000) | G11: Cash Flow
A12: Item | B12: Trade | C12: Bal B/F | D12: Apr | E12: May | F12: Jun | G12: Jul | H12: Aug | I12: Sep | J12: Oct | K12: Nov | L12: Dec | M12: Jan | N12: Feb | O12: Mar | P12: Total
A13: 1 | B13: Income
A14: 1.1 | B14: Original Contract Works | C14: 427975.16 | D14: 0 | E14: 305 | F14: 0 | G14: 0 | H14: 0 | I14: 0 | J14: 0 | K14: 0 | L14: 0 | P14: =SUM(C14:O14) -> 428280.16
A15: 1.2 | B15: V.O. / Compensation Events
A16: 1.2.1 | B16: -V.O. / C.E. | C16: 0 | D16: 0 | E16: 0 | F16: 0 | G16: 0 | H16: 0 | I16: 0 | J16: 0 | K16: 0 | L16: 0 | P16: =SUM(C16:O16) -> 0
A17: 1.2.2 | B17: -Fee of C.E. | C17: 0 | D17: 0 | E17: 0 | F17: 0 | G17: 0 | H17: 0 | I17: 0 | J17: 0 | K17: 0 | L17: 0 | P17: =SUM(C17:O17) -> 0
A18: 1.3 | B18: Provisional Sum | C18: 0 | D18: 0 | E18: 0 | F18: 0 | G18: 0 | H18: 0 | I18: 0 | J18: 0 | K18: 0 | L18: 0 | P18: =SUM(C18:O18) -> 0
A19: 1.4 | B19: Adjustment for Provisional Quantities (remeasurement) and PC Rates | C19: 0 | D19: 0 | E19: 0 | F19: 0 | G19: 0 | H19: 0 | I19: 0 | J19: 0 | K19: 0 | L19: 0 | P19: =SUM(C19:O19) -> 0
A20: 1.5 | B20: NSC | C20: 0 | D20: 0 | E20: 0 | F20: 0 | G20: 0 | H20: 0 | I20: 0 | J20: 0 | K20: 0 | L20: 0 | P20: =SUM(C20:O20) -> 0
A21: 1.6 | B21: Profit & Attendance | C21: 0 | D21: 0 | E21: 0 | F21: 0 | G21: 0 | H21: 0 | I21: 0 | J21: 0 | K21: 0 | L21: 0 | P21: =SUM(C21:O21) -> 0
A22: 1.7 | B22: Claims | C22: 0 | D22: 0 | E22: 0 | F22: 0 | G22: 0 | H22: 0 | I22: 0 | J22: 0 | K22: 0 | L22: 0 | P22: =SUM(C22:O22) -> 0
A23: 1.8 | B23: Price Fluctuation / CPF | C23: 0 | D23: 0 | E23: 0 | F23: 0 | G23: 0 | H23: 0 | I23: 0 | J23: 0 | K23: 0 | L23: 0 | P23: =SUM(C23:O23) -> 0
A24: 1.9 | B24: MPF Reimbursement | C24: 0 | D24: 0 | E24: 0 | F24: 0 | G24: 0 | H24: 0 | I24: 0 | J24: 0 | K24: 0 | L24: 0 | P24: =SUM(C24:O24) -> 0
A25: 1.10 | B25: SA | C25: 0.008 | D25: 0 | E25: 0 | F25: 0 | G25: 0 | H25: 0 | I25: 0 | J25: 0 | K25: 0 | L25: 0 | P25: =SUM(C25:O25) -> 0.008
A26: 1.11 | B26: CSD | C26: 0 | D26: 0 | E26: 0 | F26: 0 | G26: 0 | H26: 0 | I26: 0 | J26: 0 | K26: 0 | L26: 0 | P26: =SUM(C26:O26) -> 0
A27: 1.12 | B27: Other Revenue / Pain Gain Sharing
A28: 1.12.1 | B28: -Other Revenue | C28: 2223.962 | D28: 0 | E28: -2224 | F28: 0 | G28: 0 | H28: 0 | I28: 0 | J28: 0 | K28: 0 | L28: 0 | P28: =SUM(C28:O28) -> -0.038
A29: 1.12.2 | B29: -Pain Gain Sharing | C29: -1980.2005 | D29: 0 | E29: 1980 | F29: 0 | G29: 0 | H29: 0 | I29: 0 | J29: 0 | K29: 0 | L29: 0 | P29: =SUM(C29:O29) -> -0.20051
A30: 1.12.3 | B30: -Stretch Target Income | C30: 0 | D30: 0 | E30: 0 | F30: 0 | G30: 0 | H30: 0 | I30: 0 | J30: 0 | K30: 0 | L30: 0 | P30: =SUM(C30:O30) -> 0
A31: 1.13 | B31: Less :LD | C31: 0 | D31: 0 | E31: 0 | F31: 0 | G31: 0 | H31: 0 | I31: 0 | J31: 0 | K31: 0 | L31: 0 | P31: =SUM(C31:O31) -> 0
A32: 1.14 | B32: Less :Retention Money | C32: -2328.2479 | D32: 0 | E32: -61 | F32: 0 | G32: 0 | H32: 0 | I32: 0 | J32: 0 | K32: 0 | L32: 2389 | P32: =SUM(C32:O32) -> -0.24791
A33: 1.15 | B33: Less :Retention Money (NSC) | C33: 0 | D33: 0 | E33: 0 | F33: 0 | G33: 0 | H33: 0 | I33: 0 | J33: 0 | K33: 0 | L33: 0 | P33: =SUM(C33:O33) -> 0
A34: 1.16 | B34: Partialing Income Total | C34: 0 | D34: 0 | E34: 0 | F34: 0 | G34: 0 | H34: 0 | I34: 0 | J34: 0 | K34: 0 | L34: 0 | P34: =SUM(C34:O34) -> 0
A35: 1.17 | B35: Advance Payment | C35: 0 | D35: 0 | E35: 0 | F35: 0 | G35: 0 | H35: 0 | I35: 0 | J35: 0 | K35: 0 | L35: 0 | P35: =SUM(C35:O35) -> 0
B36: Total Income | C36: =SUM(C13:C35) -> 425890.69 | D36: =SUM(D13:D35) -> 0 | E36: =SUM(E13:E35) -> 0 | F36: =SUM(F13:F35) -> 0 | G36: =SUM(G13:G35) -> 0 | H36: =SUM(H13:H35) -> 0 | I36: =SUM(I13:I35) -> 0 | J36: =SUM(J13:J35) -> 0 | ... P36: =SUM(P13:P35) -> 428279.69
A38: 2 | B38: Less : Cost
A39: 2.1 | B39: Preliminaries
A40: 2.1.1 | B40: -Manpower (Mgt. & Supervision) | C40: 79994.634 | D40: 0 | E40: 0 | F40: 0 | G40: 0 | H40: 0 | I40: 0 | J40: 0 | K40: 0 | L40: 0 | P40: =SUM(C40:O40) -> 79994.634
A41: 2.1.13 | B41: -Manpower (HO-Consultant) | C41: 21.752 | D41: -3 | E41: 3.94 | F41: 0 | G41: 12.69 | H41: 37.34763 | I41: 29.81 | J41: -3.27 | K41: 3.94 | L41: 88.07 | P41: =SUM(C41:O41) -> 191.27963
A42: 2.1.2 | B42: -Manpower (RE) | C42: 122.51203 | D42: 0 | E42: 0 | F42: 0 | G42: 0 | H42: 0 | I42: 0 | J42: 0 | K42: 0 | L42: 0 | P42: =SUM(C42:O42) -> 122.51203
A43: 2.1.3 | B43: -Manpower (Labour) | C43: 15420.883 | D43: 0 | E43: 0 | F43: 0 | G43: 0 | H43: 0 | I43: 0 | J43: 0 | K43: 0 | L43: 0 | P43: =SUM(C43:O43) -> 15420.883
...
